Workbook
Name Facility_Capacity_MW: 'Inputs'!$C$7
Name Sel_ClimateZone: 'Inputs'!$C$11
Name Sel_Workload: 'Inputs'!$C$12
Name Sel_Reliability: 'Inputs'!$C$13
Name Sel_CarbonGoal: 'Inputs'!$C$14
Name Sel_HeatRejection: 'Inputs'!$C$15
Name Sel_CoolingDelivery: 'Inputs'!$C$16
Name Sel_SpeedToPower: 'Inputs'!$C$17
Name PowerMix_Grid: 'Inputs'!$C$20
Name PowerMix_Solar: 'Inputs'!$C$21
Name PowerMix_Battery: 'Inputs'!$C$22
Name PowerMix_Generator: 'Inputs'!$C$23
Name WetBulbTemp_F: 'Inputs'!$C$74
Name FreeCoolingHours: 'Inputs'!$C$75
Name ClimateWUEMult: 'Inputs'!$C$76
Name ClimateCoolingMult: 'Inputs'!$C$77
Name SolarYield_kWh_per_kW: 'Inputs'!$C$78
Name RackDensity_kW: 'Inputs'!$C$79
Name ITUtilization: 'Inputs'!$C$80
Name WorkloadCoolingMult: 'Inputs'!$C$81
Name PUEFloor: 'Inputs'!$C$82
Name StandbyLossPct: 'Inputs'!$C$83
Name UPSRedundancyFactor: 'Inputs'!$C$84
Name GenCapacityMult: 'Inputs'!$C$85
Name HeatRejectionWUEBase: 'Inputs'!$C$86
Name HeatRejectionPUEFactor: 'Inputs'!$C$87
Name ApproachTemp_F: 'Inputs'!$C$88
Name Hours_Per_Year: 'Constants'!$B$5
Name Liters_Per_Gallon: 'Constants'!$B$6
Name kWh_Per_MWh: 'Constants'!$B$7
Name kW_Per_MW: 'Constants'!$B$8
Name Grid_Carbon_Intensity: 'Assumptions'!$C$21
Name Diesel_Carbon_Intensity: 'Assumptions'!$C$23
Name UPS_Efficiency: 'Equipment Efficiencies'!$B$6
Name Transformer_Efficiency: 'Equipment Efficiencies'!$B$7
Name Distribution_Loss_Pct: 'Equipment Efficiencies'!$B$8
Name DLC_Heat_Capture_Fraction: 'Equipment Efficiencies'!$B$9
Name Residual_Room_Heat_Fraction: 'Equipment Efficiencies'!$B$10
Name Recoverable_Heat_Fraction: 'Equipment Efficiencies'!$B$11
Name Cooling_Share_of_Overhead: 'Equipment Efficiencies'!$B$12
Name Aux_Share_of_Overhead: 'Equipment Efficiencies'!$B$13
Name CDU_Effectiveness: 'Equipment Efficiencies'!$B$14
Name Pump_Efficiency: 'Equipment Efficiencies'!$B$15
Name Fan_Efficiency: 'Equipment Efficiencies'!$B$16
Name FreeCooling_Load_Reduction_Effectiveness: 'Equipment Efficiencies'!$B$17
Name Pump_Share_of_Cooling_Load: 'Equipment Efficiencies'!$B$21
Name Fan_Share_of_Cooling_Load: 'Equipment Efficiencies'!$B$22
Name Evap_Evaporated_Share: 'Equipment Efficiencies'!$B$23
Name Adiabatic_Evaporated_Share: 'Equipment Efficiencies'!$B$24
Name Utility_Transformer_Loss_Pct: 'Equipment Efficiencies'!$B$28
Name LV_Switchgear_Loss_Pct: 'Equipment Efficiencies'!$B$29
Name UPS_Heat_Loss_Pct_Base: 'Equipment Efficiencies'!$B$30
Name rPDU_Loss_Pct: 'Equipment Efficiencies'!$B$31
Name Server_Heat_Loss_Pct: 'Equipment Efficiencies'!$B$32
Name ITMix_GPU: 'Equipment Efficiencies'!$B$35
Name ITMix_TPU: 'Equipment Efficiencies'!$B$36
Name ITMix_CPU: 'Equipment Efficiencies'!$B$37
Name ITMix_ASIC: 'Equipment Efficiencies'!$B$38
Name ITMix_MPU: 'Equipment Efficiencies'!$B$39
Name ITMix_Fans: 'Equipment Efficiencies'!$B$40

Sheet Inputs
A1: INPUTS — 100 MW Hyperscale AI Data Center, California
A3: Edit only the yellow cells. All other cells are formulas or fixed reference data — do not overwrite. See the Assumptions and Equations sheets for full documentation of every value used below.
A5: FIXED PARAMETERS
A6: Location | C6: California
A7: Facility Capacity (IT Critical Load) | C7: 100 | D7: MW
A8: Base Redundancy Topology | C8: N+1
A10: USER-ADJUSTABLE SCENARIO INPUTS (yellow cells — choose from dropdown)
A11: Climate Zone | C11: CZ4 San Jose
A12: Primary Workload | C12: AI Training
A13: Reliability Tier | C13: High (99.99%)
A14: Carbon / Sustainability Goal | C14: Annual Renewable Matching
A15: Primary Heat Rejection Method | C15: Closed-loop Evaporative Cooling
A16: Cooling Delivery Technology | C16: Direct-to-Chip Liquid Cooling
A17: Speed to Power | C17: 2-5 years
A19: POWER MIX (user sliders — % of total facility electricity draw, must sum to 100%)
A20: Grid (CAISO) | C20: 0.55
A21: On-site Solar PV | C21: 0.3
A22: Battery Discharge (BESS) | C22: 0.15
A23: Generator (active run) | C23: 0
A24: Total (must equal 100%) | C24: =C20+C21+C22+C23
A26: SUGGESTED POWER MIX (informational reference only — derived from Carbon Goal & Speed to Power)
A27: Suggested Grid % (from Carbon Goal) | C27: =INDEX($B$58:$B$60,MATCH($C$14,$A$58:$A$60,0))
A28: Suggested Solar % (from Carbon Goal) | C28: =INDEX($C$58:$C$60,MATCH($C$14,$A$58:$A$60,0))
A29: Suggested Battery % (from Carbon Goal) | C29: =INDEX($D$58:$D$60,MATCH($C$14,$A$58:$A$60,0))
A30: Grid Availability Factor (from Speed to Power) | C30: =INDEX($B$69:$B$71,MATCH($C$17,$A$69:$A$71,0))
A31: Behind-the-Meter Solar Bias (from Speed to Power) | C31: =INDEX($C$69:$C$71,MATCH($C$17,$A$69:$A$71,0))
A32: Battery Sizing Multiplier (from Speed to Power) | C32: =INDEX($D$69:$D$71,MATCH($C$17,$A$69:$A$71,0))
A34: REFERENCE TABLE — Climate Zone (source: CEC Climate Zones; ASHRAE 169 design wet-bulb methodology; NREL PVWatts)
A35: Zone | B35: Representative Location | C35: Design Wet-Bulb Temp (°F) | D35: Free Cooling Hours (hr/yr) | E35: WUE Multiplier | F35: Cooling Energy Multiplier | G35: Solar Yield (kWh/kW-yr)
A36: CZ3 Bay Area | B36: Oakland / East Bay | C36: 63 | D36: 6500 | E36: 0.85 | F36: 0.85 | G36: 1550
A37: CZ4 San Jose | B37: San Jose / Silicon Valley | C37: 65 | D37: 6000 | E37: 0.9 | F37: 0.9 | G37: 1600
A38: CZ11 | B38: Red Bluff / Sacramento Valley (N) | C38: 70 | D38: 4500 | E38: 1.05 | F38: 1.1 | G38: 1680
A39: CZ12 | B39: Sacramento | C39: 69 | D39: 4800 | E39: 1 | F39: 1.05 | G39: 1650
A40: CZ13 | B40: Fresno / Stockton corridor | C40: 71 | D40: 4300 | E40: 1.1 | F40: 1.15 | G40: 1700
A41: CZ15 Desert | B41: Imperial / Palm Springs (desert) | C41: 76 | D41: 2500 | E41: 1.3 | F41: 1.3 | G41: 1850
A43: REFERENCE TABLE — Workload (source: ASHRAE TC9.9 Thermal Guidelines; LBNL data center benchmarking)
A44: Workload | B44: Rack Density (kW/rack) | C44: IT Utilization (%) | D44: Cooling Load Multiplier | E44: PUE Floor
A45: AI Training | B45: 80 | C45: 0.92 | D45: 1.15 | E45: 1.1
A46: AI Inference | B46: 45 | C46: 0.75 | D46: 1 | E46: 1.15
A47: HPC | B47: 60 | C47: 0.85 | D47: 1.08 | E47: 1.12
...

Sheet Constants
A1: CONSTANTS — Physical & Unit Conversion Constants
A3: Universal constants used throughout the model. Not scenario-dependent.
A5: Hours per Year | C5: 8760 | D5: hr/yr
A6: Liters per US Gallon | C6: 3.78541
A7: kWh per MWh | C7: 1000
A8: kW per MW | C8: 1000

Sheet Assumptions
A1: ASSUMPTIONS — Full Documentation of Every Engineering Assumption
A3: Every hardcoded coefficient in this workbook is documented here with its source, publication, and year. Values marked 'Representative' are engineering estimates consistent with the cited organization's published ranges/methodology, not a directly-quoted figure — verify against the primary source before detailed engineering use.
A5: Category | B5: Assumption | C5: Value | D5: Units | E5: Source Org | F5: Publication | G5: Year | H5: Notes
A6: Equipment Efficiency | B6: UPS Efficiency | C6: 0.97 | D6: fraction | E6: LBNL | F6: United States Data Center Energy Usage Report | G6: 2016 | H6: Representative value for modern double-conversion / lithium-ion UPS; industry-typical range 0.95-0.98
A7: Equipment Efficiency | B7: Transformer Efficiency | C7: 0.99 | D7: fraction | E7: DOE | F7: Better Buildings — Data Center Efficiency | G7: ongoing | H7: Representative dry-type transformer efficiency at rated load
A8: Equipment Efficiency | B8: Electrical Distribution Loss | C8: 0.01 | D8: fraction | E8: LBNL | F8: United States Data Center Energy Usage Report | G8: 2016 | H8: Representative facility-level busway/PDU/cabling loss beyond UPS and transformer stages
A9: Heat Capture | B9: Direct-to-Chip Heat Capture Fraction | C9: 0.75 | D9: fraction | E9: ASHRAE TC9.9 | F9: Liquid Cooling Guidelines | G9: 2021 | H9: Representative fraction of chip heat captured directly to coolant; remainder rejected to room air via CRAH
A10: Heat Capture | B10: Residual Room Heat Fraction | C10: 0.25 | D10: fraction | E10: ASHRAE TC9.9 | F10: Liquid Cooling Guidelines | G10: 2021 | H10: Equals 1 minus the Direct-to-Chip Heat Capture Fraction above
A11: Heat Recovery | B11: Recoverable Fraction of Coolant Heat | C11: 0.25 | D11: fraction | E11: RenewIT Project | F11: Green Data Centres | G11: 2016 | H11: Representative fraction of captured coolant-loop heat available at a usable temperature for heat-reuse applications
A12: Cooling | B12: Cooling Share of Non-IT Overhead | C12: 0.85 | D12: fraction | E12: LBNL | F12: Data center benchmarking studies | G12: various | H12: Representative split of (PUE-1) overhead between the cooling plant and lighting/auxiliary loads
A13: Cooling | B13: Lighting/Aux Share of Non-IT Overhead | C13: 0.15 | D13: fraction | E13: LBNL | F13: Data center benchmarking studies | G13: various | H13: Equals 1 minus the Cooling Share of Non-IT Overhead above
A14: Cooling | B14: CDU Thermal Effectiveness | C14: 0.95 | D14: fraction | E14: ASHRAE TC9.9 | F14: Liquid Cooling Guidelines | G14: 2021 | H14: Representative Coolant Distribution Unit (CDU) heat-exchanger effectiveness
A15: Cooling | B15: Pump Efficiency | C15: 0.78 | D15: fraction | E15: DOE | F15: Better Buildings — Data Center Efficiency | G15: ongoing | H15: Representative wire-to-water efficiency for centrifugal circulation pumps
A16: Cooling | B16: Fan Efficiency | C16: 0.7 | D16: fraction | E16: DOE | F16: Better Buildings — Data Center Efficiency | G16: ongoing | H16: Representative efficiency for cooling-tower / dry-cooler fans
A17: Cooling | B17: Free-Cooling Load Reduction Effectiveness | C17: 0.6 | D17: fraction | E17: ASHRAE TC9.9 | F17: Economizer / free-cooling guidance | G17: various | H17: Representative reduction in mechanical cooling energy achieved during free-cooling hours (vs full mechanical load)
A18: Water | B18: Evaporative Cooling — Evaporated Share | C18: 0.8 | D18: fraction | E18: The Green Grid | F18: Water Usage Effectiveness (WUE) white paper | G18: 2011 | H18: Representative share of cooling-tower makeup water lost to evaporation vs blowdown, at typical cycles of concentration
A19: Water | B19: Evaporative Cooling — Blowdown Share | C19: 0.2 | D19: fraction | E19: The Green Grid | F19: Water Usage Effectiveness (WUE) white paper | G19: 2011 | H19: Equals 1 minus the Evaporative Cooling Evaporated Share above
A20: Water | B20: Adiabatic Dry Cooler — Blowdown Share | C20: 0.05 | D20: fraction | E20: ASHRAE TC9.9 | F20: Liquid Cooling Guidelines | G20: 2021 | H20: Representative: adiabatic pre-cooling uses water intermittently with minimal blowdown
A21: Carbon | B21: CAISO Grid Carbon Intensity | C21: 0.225 | D21: kg CO2/kWh | E21: CAISO / EPA | F21: CAISO Fuel Mix; EPA eGRID (CAMX subregion) | G21: 2023 | H21: Representative annual average; actual intensity varies hourly — production deployment should call the CAISO real-time API
A22: Carbon | B22: Solar / Battery Carbon Intensity | C22: 0 | D22: kg CO2/kWh | E22: Model assumption | F22: n/a | G22: n/a | H22: Battery discharge treated as carbon-free on the modeling assumption that BESS is predominantly charged from on-site solar in this scenario
A23: Carbon | B23: Diesel Generator Carbon Intensity | C23: 0.7 | D23: kg CO2/kWh | E23: EPA | F23: Emission Factors for Greenhouse Gas Inventories | G23: 2023 | H23: Representative diesel standby generator emission factor
A24: Climate | B24: California Climate Zone parameters (wet-bulb, free-cooling hours, solar yield) | D24: see Inputs sheet | E24: CEC / ASHRAE / NREL | F24: CEC Climate Zones 1-16; ASHRAE 169 Climatic Design Conditions; NREL PVWatts | G24: various | H24: Representative engineering estimates by California climate zone — see Climate Zone Reference Table on the Inputs sheet; verify against local ASHRAE 169 station data for detailed design
A25: Cooling | B25: Pump Share of Cooling Electrical Load | C25: 0.2 | D25: fraction | E25: DOE | F25: Better Buildings — Data Center Efficiency | G25: ongoing | H25: Representative illustrative split of cooling-plant electrical draw attributable to circulation pumps
A26: Cooling | B26: Fan Share of Cooling Electrical Load | C26: 0.15 | D26: fraction | E26: DOE | F26: Better Buildings — Data Center Efficiency | G26: ongoing | H26: Representative illustrative split of cooling-plant electrical draw attributable to tower/dry-cooler fans
A27: Water | B27: Evaporative Cooling — Evaporated Share | C27: 0.8 | D27: fraction | E27: The Green Grid | F27: Water Usage Effectiveness (WUE) white paper | G27: 2011 | H27: Duplicate of the earlier Water-category row; kept adjacent to its Adiabatic counterpart for readability
A28: Water | B28: Adiabatic Dry Cooler — Evaporated Share | C28: 0.95 | D28: fraction | E28: ASHRAE TC9.9 | F28: Liquid Cooling Guidelines | G28: 2021 | H28: Representative: adiabatic pre-cooling water evaporates almost entirely, with minimal blowdown/drain
A29: Electrical (granular) | B29: Utility Transformer Loss (MV->480V) | C29: 0.005 | D29: fraction | E29: User-provided reference diagram | F29: Power-flow block diagram | G29: n/a | H29: Explicit loss value labeled on the reference diagram, not a generic industry figure
A30: Electrical (granular) | B30: LV Switchgear Loss | C30: 0.002 | D30: fraction | E30: User-provided reference diagram | F30: Power-flow block diagram | G30: n/a | H30: Explicit loss value labeled on the reference diagram
A31: Electrical (granular) | B31: UPS Heat Loss (baseline) | C31: 0.02 | D31: fraction | E31: User-provided reference diagram | F31: Power-flow block diagram | G31: n/a | H31: Explicit loss value labeled on the reference diagram; scaled by the Reliability-tier UPS Redundancy Overhead Factor in the model
A32: Electrical (granular) | B32: Rack PDU (rPDU) Loss | C32: 0.01 | D32: fraction | E32: User-provided reference diagram | F32: Power-flow block diagram | G32: n/a | H32: Reference diagram labels both '1%' and '2% Heat' near the two rPDU paths; the smaller, more conservative value is used as the modeled figure
A33: Electrical (granular) | B33: Server Heat Loss Fraction | C33: 0.97 | D33: fraction | E33: User-provided reference diagram | F33: Power-flow block diagram | G33: n/a | H33: Reference diagram labels this range as 95-99%; midpoint used as the representative point value

Sheet Equipment Efficiencies
A1: EQUIPMENT EFFICIENCIES — Quick-Reference Lookup Used by the Flow Sheets
A3: Operational lookup layer pulled from the Assumptions sheet (full source/citation detail lives there). Flow sheets reference the named ranges defined here.
A5: Equipment / Parameter | B5: Value | C5: Units | D5: Notes
A6: UPS Efficiency | B6: 0.97 | C6: fraction | D6: See Assumptions sheet
A7: Transformer Efficiency | B7: 0.99 | C7: fraction | D7: See Assumptions sheet
A8: Electrical Distribution Loss | B8: 0.01 | C8: fraction | D8: See Assumptions sheet
A9: Direct-to-Chip Heat Capture Fraction | B9: 0.75 | C9: fraction | D9: See Assumptions sheet
A10: Residual Room Heat Fraction | B10: =1-B9 | C10: fraction | D10: Equals 1 minus the Heat Capture Fraction above
A11: Recoverable Fraction of Coolant Heat | B11: 0.25 | C11: fraction | D11: See Assumptions sheet
A12: Cooling Share of Non-IT Overhead | B12: 0.85 | C12: fraction | D12: See Assumptions sheet
A13: Aux/Lighting Share of Non-IT Overhead | B13: =1-B12 | C13: fraction | D13: Equals 1 minus the Cooling Share above
A14: CDU Thermal Effectiveness | B14: 0.95 | C14: fraction | D14: See Assumptions sheet
A15: Pump Efficiency | B15: 0.78 | C15: fraction | D15: See Assumptions sheet
A16: Fan Efficiency | B16: 0.7 | C16: fraction | D16: See Assumptions sheet
A17: Free-Cooling Load Reduction Effectiveness | B17: 0.6 | C17: fraction | D17: See Assumptions sheet
A20: Additional splits used by Cooling Flow / Water Flow sheets
A21: Pump Share of Cooling Electrical Load | B21: 0.2 | C21: fraction | D21: See Assumptions sheet
A22: Fan Share of Cooling Electrical Load | B22: 0.15 | C22: fraction | D22: See Assumptions sheet
A23: Evaporative Cooling — Evaporated Share | B23: 0.8 | C23: fraction | D23: See Assumptions sheet
A24: Adiabatic Dry Cooler — Evaporated Share | B24: 0.95 | C24: fraction | D24: See Assumptions sheet
A27: Granular power-flow topology constants (source: user-provided reference diagram)
A28: Utility Transformer Loss (MV->480V) | B28: 0.005 | C28: fraction | D28: Reference diagram
A29: LV Switchgear Loss | B29: 0.002 | C29: fraction | D29: Reference diagram
A30: UPS Heat Loss (baseline, before Reliability-tier scaling) | B30: 0.02 | C30: fraction | D30: Reference diagram
A31: Rack PDU (rPDU) Loss | B31: 0.01 | C31: fraction | D31: Reference diagram
A32: Server Heat Loss Fraction (chip power -> heat) | B32: 0.97 | C32: fraction | D32: Reference diagram (95-99% range, midpoint used)
A34: Illustrative splits — reference diagram shows the branches but not their relative sizes
A35: IT Hardware Mix — GPU share | B35: 0.55 | C35: fraction | D35: Illustrative, AI-training-weighted fleet
A36: IT Hardware Mix — TPU share | B36: 0.15 | C36: fraction | D36: Illustrative, AI-training-weighted fleet
A37: IT Hardware Mix — CPU share | B37: 0.12 | C37: fraction | D37: Illustrative, AI-training-weighted fleet
A38: IT Hardware Mix — ASIC share | B38: 0.08 | C38: fraction | D38: Illustrative, AI-training-weighted fleet
A39: IT Hardware Mix — MPU share | B39: 0.06 | C39: fraction | D39: Illustrative, AI-training-weighted fleet
A40: IT Hardware Mix — Server Fans share | B40: 0.04 | C40: fraction | D40: Illustrative, AI-training-weighted fleet
A41: CRAH Split — Room/White Space share | B41: 0.6 | C41: fraction | D41: Illustrative
A42: CRAH Split — Server Hall share | B42: 0.4 | C42: fraction | D42: Illustrative
A43: Room/White Space — Electrical Rooms share | B43: 0.4 | C43: fraction | D43: Illustrative
A44: Room/White Space — Offices & Control Rooms share | B44: 0.35 | C44: fraction | D44: Illustrative
A45: Room/White Space — Battery Rooms share | B45: 0.25 | C45: fraction | D45: Illustrative
A46: Server Hall — Networking share | B46: 0.55 | C46: fraction | D46: Illustrative
... A52: Recoverable Heat End-Use — Industrial Process share | B52: 0.1 | C52: fraction | D52: Illustrative

Sheet Electricity Flow
A1: ELECTRICITY FLOW — Utility/Solar/ESS/Generator → Chip, full granular chain
A3: Matches the user-provided power-flow reference diagram node-for-node: Utility Grid / On-site Solar / ESS / Generator each through their own conversion equipment to the Main MV Bus, then MV Switchgear → Utility Transformer (0.5% loss) → LV Switchgear (0.2% loss) → ATS → IT Infrastructure/Servers vs. Lighting & Building Auxiliary Loads. The IT path continues UPS (2% heat, N+1) → Distribution Panels & Switchboards → PDUs → rPDUs (1% loss) → Server PSU → Motherboard → CPU/MPU/GPU/TPU/ASIC/Fans. Computed BACKWARD from the 100MW IT Load at the chip, so every upstream stage shows what it must actually deliver.
A5: EFFICIENCY / PUE CALCULATION
A6: Modeled Cooling PUE (drives the Lighting & Aux sizing below — see headline PUE further down, which additionally includes electrical conversion losses) | C6: =1+(PUEFloor-1)*ClimateCoolingMult*HeatRejectionPUEFactor+StandbyLossPct
A7: WUE (Water Usage Effectiveness) | C7: =HeatRejectionWUEBase*ClimateWUEMult | D7: L/kWh
A9: DATA HALL / SERVER (MW, peak/design — computed first since everything upstream is sized to deliver this)
A10: IT Load at chip/server (100MW design capacity) | C10: =Facility_Capacity_MW | D10: MW
A11: Total Facility Load (IT + Lighting & Aux, via Modeled Cooling PUE) | C11: =B10*B6 | D11: MW
A12: Lighting & Building Auxiliary Loads (Total Facility − IT) | C12: =B11-B10 | D12: MW
A14: Server PSU / Motherboard (pass-through, = IT Load) | C14: =B10 | D14: MW
A15: GPU (Graphics Processing Unit) | C15: =$B$10*ITMix_GPU | D15: MW
A16: TPU (Tensor Processing Unit) | C16: =$B$10*ITMix_TPU | D16: MW
A17: CPU | C17: =$B$10*ITMix_CPU | D17: MW
A18: ASIC (Application-Specific Integrated Circuit) | C18: =$B$10*ITMix_ASIC | D18: MW
A19: Multi-Processor Servers (MPU) | C19: =$B$10*ITMix_MPU | D19: MW
A20: Server Fans | C20: =$B$10*ITMix_Fans | D20: MW
A22: FACILITY LEVEL (working backward: rPDU → PDU → Distribution Panels → UPS, IT path only)
A23: Rack PDU (rPDU) Input | C23: =B10/(1-rPDU_Loss_Pct) | D23: MW
A24: rPDU Loss (1%, per reference diagram) | C24: =B23-B10 | D24: MW
A25: Power Distribution Units (PDUs) Input (pass-through) | C25: =B23 | D25: MW
A26: Distribution Panels & Switchboards Input (pass-through) | C26: =B25 | D26: MW
A27: Effective UPS Heat Loss % (baseline × Reliability-tier redundancy factor) | C27: =MIN(0.30,UPS_Heat_Loss_Pct_Base*UPSRedundancyFactor)
A28: UPS Input (N+1, two units) | C28: =B26/(1-B27) | D28: MW
A29: UPS Heat Loss | C29: =B28-B26 | D29: MW
A31: CAMPUS INFRASTRUCTURE (ATS → LV Switchgear → Utility Transformer → MV Switchgear)
A32: Automatic Transfer Switch (ATS) Input = UPS Input + Lighting & Aux | C32: =B28+B12 | D32: MW
A33: LV Switchgear Input | C33: =B32/(1-LV_Switchgear_Loss_Pct) | D33: MW
A34: LV Switchgear Loss (0.2%, per reference diagram) | C34: =B33-B32 | D34: MW
A35: Utility Transformer Input (MV→480V) = MV Switchgear Output | C35: =B33/(1-Utility_Transformer_Loss_Pct) | D35: MW
A36: Utility Transformer Loss (0.5%, per reference diagram) | C36: =B35-B33 | D36: MW
A37: Main Medium Voltage BUS / MV Switchgear (pass-through) | C37: =B35 | D37: MW
A38: PUE (headline — Main MV Bus Input ÷ IT Load, measured at the utility meter) | C38: =B37/B10
A40: UTILITY LEVEL — SOURCE SPLIT (Grid + Solar + ESS/Battery + Generator, per Power Mix sliders, each through its own conversion path)
A41: Utility Grid → HV Transmission → Main MV Bus | C41: =$B$37*PowerMix_Grid | D41: MW
A42: On-site Solar → PV Inverter → Main MV Bus | C42: =$B$37*PowerMix_Solar | D42: MW
A43: ESS → PCS (Power Conversion System) → Main MV Bus | C43: =$B$37*PowerMix_Battery | D43: MW
A44: Generator → Generator Breaker → Main MV Bus (active run) | C44: =$B$37*PowerMix_Generator | D44: MW
A45: Generator Reserve Capacity (standby, not dispatched) | C45: =B10*GenCapacityMult | D45: MW
A47: ANNUAL ENERGY & CARBON (applies resolved IT Utilization across 8,760 hr/yr)
A48: Total Annual Electricity | C48: =$B$37*ITUtilization*Hours_Per_Year | D48: MWh/yr
...

Sheet Cooling Flow
A1: COOLING FLOW — Liquid Cooling Loop (CDU) + Air Cooling Loop (CRAH), full equipment chain
A3: Matches the reference diagram's two parallel cooling paths. Liquid loop (serves 100% of chip heat, per the diagram's single 'Heat loss from server' arrow): Onsite Pump → HVAC → Closed Loop Evaporative → Chiller → Facility Water Loop → Heat Exchanger → CDU → Direct Liquid Cooling → Secondary Coolant → Cold Plates. Each of these is a closed-loop pass-through stage (same MW-th value throughout) until Heat Exchanger, where the Heat Recovery sheet splits it into rejected-via-Chiller vs. candidate-for-recovery. Air loop (serves non-IT facility spaces — networking, storage, electrical/battery rooms, offices): HVAC → CRAH → Room/White Space + Server Hall, sized off Lighting & Building Aux electrical load since virtually all of it becomes heat. The CRAH sub-branch splits are illustrative (reference diagram shows the branches, not their relative sizes) — see Equipment Efficiencies sheet for each documented split.
A5: COOLING PLANT ELECTRICAL LOAD (MW, peak/design)
A6: Cooling / HVAC Plant Electrical Load | C6: =Lighting_Aux_Peak_MW*MIN(0.98,Cooling_Share_of_Overhead*WorkloadCoolingMult) | D6: MW
A7: Pump Energy | C7: =B6*Pump_Share_of_Cooling_Load | D7: MW
A8: Fan Energy | C8: =B6*Fan_Share_of_Cooling_Load | D8: MW
A10: LIQUID COOLING LOOP (MW-th, closed-loop equipment chain — carries 100% of Chip Heat)
A11: Onsite Pump (pass-through) | C11: =Chip_Heat_Peak_MW | D11: MW-th
A12: HVAC (pass-through, liquid branch) | C12: =B11 | D12: MW-th
A13: Closed Loop Evaporative (pass-through) | C13: =B12 | D13: MW-th
A14: Chiller (pass-through) | C14: =B13 | D14: MW-th
A15: Facility Water Loop (pass-through) | C15: =B14 | D15: MW-th
A16: Heat Exchanger (pass-through — split into recovered/rejected on Heat Recovery sheet) | C16: =B15 | D16: MW-th
A17: CDU (Coolant Distribution Unit, pass-through) | C17: =B16 | D17: MW-th
A18: Servers/IT Equipment (Direct Liquid Cooling, pass-through) | C18: =B17 | D18: MW-th
A19: Secondary Coolant (pass-through) | C19: =B18 | D19: MW-th
A20: Cold Plates → Cold Supply Water (pass-through, chip-level delivery) | C20: =B19 | D20: MW-th
A21: Return Water (closed loop, back to HVAC) | C21: =B20 | D21: MW-th
A23: AIR COOLING LOOP (MW, CRAH branch — sized off Lighting & Aux electrical load)
A24: CRAH (Computer Room Air Handlers) | C24: =Lighting_Aux_Peak_MW | D24: MW
A25: Room/White Space | C25: =B24*CRAH_RoomShare | D25: MW
A26: Server Hall | C26: =B24*CRAH_ServerHallShare | D26: MW
A27: Electrical Rooms | C27: =B25*Room_ElecShare | D27: MW
A28: Offices & Control Rooms | C28: =B25*Room_OfficeShare | D28: MW
A29: Battery Rooms | C29: =B25*Room_BatteryShare | D29: MW
A30: Networking | C30: =B26*Hall_NetworkingShare | D30: MW
A31: Storage | C31: =B26*Hall_StorageShare | D31: MW
A33: HEAT REJECTION CHARACTERISTICS (from selected Primary Heat Rejection Method)
A34: Primary Heat Rejection Method | C34: =Sel_HeatRejection
A35: Approach Temperature | C35: =ApproachTemp_F | D35: °F
A37: FREE-COOLING OFFSET & ANNUAL COOLING ENERGY
A38: Free Cooling Hours | C38: =FreeCoolingHours | D38: hr/yr
A39: Mechanical Load Reduction During Free-Cooling Hours | C39: =(B38/Hours_Per_Year)*FreeCooling_Load_Reduction_Effectiveness
A40: Annual Cooling Energy — design-basis | C40: =B6*ITUtilization*Hours_Per_Year | D40: MWh/yr
A41: Annual Cooling Energy — net of free-cooling offset | C41: =B40*(1-B39) | D41: MWh/yr

Sheet Water Flow
A1: WATER FLOW — Water Source → Onsite Pump → HVAC → Closed Loop Evaporative → Chiller → Water Losses
A3: This is the mass-balance (gallons) accounting for the open/evaporative portion of the cooling system. The named equipment chain — Onsite Pump, HVAC, Closed Loop Evaporative, Chiller, Facility Water Loop, Heat Exchanger, CDU, Direct Liquid Cooling, Secondary Coolant, Cold Plates — is modeled on the Cooling Flow sheet as a closed secondary loop (MW-th, no additional water consumption past the Chiller stage). WUE follows The Green Grid definition: annual water usage per unit of annual IT energy. Evaporated/blowdown split depends on the selected Primary Heat Rejection Method.
A5: WATER USE EFFECTIVENESS
A6: WUE (Water Usage Effectiveness) | C6: =WUE | D6: L/kWh
A8: ANNUAL WATER CONSUMPTION
A9: Annual IT Energy (WUE basis) | C9: =Annual_IT_Energy_MWh | D9: MWh/yr
A10: Annual Water Consumption | C10: =B6*B9*kWh_Per_MWh | D10: L/yr
A11: Annual Water Consumption | C11: =B10/Liters_Per_Gallon | D11: gal/yr
A13: EVAPORATED vs. BLOWDOWN SPLIT (method-dependent)
A14: Evaporated Share | C14: =IF(Sel_HeatRejection="Closed-loop Evaporative Cooling",Evap_Evaporated_Share,Adiabatic_Evaporated_Share)
A15: Evaporated (Consumed) | C15: =B11*B14 | D15: gal/yr
A16: Blowdown / Discharge | C16: =B11*(1-B14) | D16: gal/yr

Sheet Heat Recovery
A1: HEAT RECOVERY — Server + Infrastructure Heat → Heat Loss → Recoverable Heat → 5 End Uses
A3: Matches the reference diagram's two heat sources converging on 'Heat Loss': (1) server heat (95-99% of chip power, entering the liquid loop at Heat Exchanger, which splits into Chiller-rejected vs. recovery-candidate), and (2) infrastructure heat loss (the sum of the Utility Transformer, LV Switchgear, UPS, and rPDU losses modeled on the Electricity Flow sheet). 'Heat Loss' passes straight through to 'Recoverable Heat' (the diagram shows no further split there), which then branches to 5 end uses. That 5-way split has no numeric source in the reference diagram — illustrative shares are documented on the Equipment Efficiencies sheet.
A5: SERVER HEAT (MW-thermal, at 100% of design IT load)
A6: Chip Heat (IT Load × Server Heat Loss Fraction) | C6: =IT_Load_Peak_MW*Server_Heat_Loss_Pct | D6: MW-th
A7: To Heat Exchanger (100% of chip heat, via liquid loop) | C7: =B6 | D7: MW-th
A8: Heat Exchanger → Chiller (Heat Rejection, not recovered) | C8: =B7*(1-Recoverable_Heat_Fraction) | D8: MW-th
A9: Heat Exchanger → Heat Loss (recovery candidate) | C9: =B7*Recoverable_Heat_Fraction | D9: MW-th
A11: INFRASTRUCTURE HEAT LOSS (MW, sum of the 4 electrical-conversion losses on Electricity Flow)
A12: Infrastructure Heat Loss (Transformer + LV Switchgear + UPS + rPDU) | C12: ='Electricity Flow'!B36+'Electricity Flow'!B34+'Electricity Flow'!B29+'Electricity Flow'!B24 | D12: MW
A14: HEAT LOSS → RECOVERABLE HEAT → 5 END USES (MW-thermal)
A15: Heat Loss (Heat Exchanger candidate + Infrastructure) | C15: =B9+B12 | D15: MW-th
A16: Recoverable Heat (pass-through from Heat Loss) | C16: =B15 | D16: MW-th
A17: Thermal Energy Network (TEN) | C17: =B16*HeatEnd_TEN | D17: MW-th
A18: Campus Hot Water | C18: =B16*HeatEnd_CampusHotWater | D18: MW-th
A19: Absorption Chiller | C19: =B16*HeatEnd_AbsorptionChiller | D19: MW-th
A20: Thermal Energy Storage | C20: =B16*HeatEnd_ThermalStorage | D20: MW-th
A21: Industrial Process | C21: =B16*HeatEnd_IndustrialProcess | D21: MW-th
A23: HEADLINE READOUT & ANNUAL HEAT ENERGY
A24: Recoverable Heat % (of total server + infrastructure heat) | C24: =B16/(B6+B12)
A25: Annual Waste Heat (server, IT-energy basis) | C25: =Annual_IT_Energy_MWh | D25: MWh-th/yr
A26: Annual Recoverable Heat | C26: =B25*B24 | D26: MWh-th/yr

Sheet Equations
A1: EQUATIONS — Documentation of Every Calculated Output
A3: Engineering basis for each calculated field. 'Assumptions Used' cross-references rows on the Assumptions sheet; 'Cell Reference' points to the live formula.
A5: Output | B5: Engineering Equation | C5: Variable Definitions | D5: Units | E5: Source / Basis | F5: Assumptions Used | G5: Cell Reference
A6: PUE | B6: Two-stage model. (1) Modeled Cooling PUE = 1 + (PUEfloor − 1) × Cclimate × Creject + Lstandby, sizes the Lighting & Aux load. (2) Headline PUE = Main_MV_Bus_Input_MW ÷ IT_Load_MW — total facility power at the utility meter ÷ IT power, matching The Green Grid's standard PUE definition since it captures all four granular conversion losses (Transformer, LV Switchgear, UPS, rPDU) that stage (1) excludes. | C6: PUEfloor = workload PUE floor; Cclimate = climate cooling multiplier; Creject = heat-rejection PUE factor; Lstandby = reliability standby loss; Main_MV_Bus_Input_MW = total electrical draw entering the Main MV Bus from Grid+Solar+ESS+Generator combined | D6: ratio | E6: The Green Grid PUE: A Comprehensive Examination of the Metric (2012) | F6: Workload, Climate Zone, Heat Rejection, Reliability tables (Inputs sheet) | G6: 'Electricity Flow'!B6 (modeled cooling PUE); 'Electricity Flow'!B38 (headline PUE)
A7: WUE | B7: WUE = WUEbase × Mclimate | C7: WUEbase = heat-rejection method's base water use; Mclimate = climate WUE multiplier | D7: L/kWh | E7: The Green Grid WUE white paper (2011) | F7: Heat Rejection & Climate Zone tables (Inputs sheet) | G7: 'Electricity Flow'!B7
A8: Total Annual Electricity | B8: Annual_MWh = Main_MV_Bus_Input_MW × ITUtilization × 8760 | C8: Main_MV_Bus_Input_MW = total facility draw at the utility interconnection; ITUtilization = resolved workload utilization | D8: MWh/yr | E8: Standard annualization of a design-basis peak load | F8: Workload IT Utilization (Inputs sheet) | G8: 'Electricity Flow'!B48
A9: IT Energy | B9: IT_MWh = IT_Load_MW × ITUtilization × 8760 | C9: IT_Load_MW = 100 MW fixed facility capacity | D9: MWh/yr | E9: Direct annualization | F9: n/a | G9: 'Electricity Flow'!B49
A10: Cooling Energy | B10: Cooling_MW = Lighting_Aux_MW × Cooling_Share_of_Overhead × WorkloadCoolingMult, capped at 98% | C10: Lighting_Aux_MW = Total Facility − IT Load (the diagram's single ATS branch covering all non-IT load) | D10: MW / MWh-yr | E10: LBNL data center benchmarking (overhead split) | F10: Cooling Share of Non-IT Overhead; Workload Cooling Load Multiplier | G10: 'Cooling Flow'!B6
A11: UPS Heat Loss | B11: UPS_Loss_MW = UPS_Input_MW − Distribution_Panels_Input_MW, where UPS_Input = Distribution_Panels_Input ÷ (1 − MIN(30%, 2% × UPS_Redundancy_Factor)) | C11: 2% = baseline UPS heat loss labeled on the reference diagram; UPS_Redundancy_Factor = overhead multiplier from selected Reliability tier | D11: MW | E11: User-provided reference diagram (baseline); Reliability-tier scaling per Uptime Institute Tier Standard | F11: UPS Heat Loss (baseline); Reliability Tier table | G11: 'Electricity Flow'!B29
A12: Utility Transformer Loss | B12: Xfmr_Loss_MW = Xfmr_Input_MW − LV_Switchgear_Input_MW, where Xfmr_Input = LV_Switchgear_Input ÷ (1 − 0.5%) | C12: 0.5% = loss labeled on the reference diagram for the MV→480V utility transformer | D12: MW | E12: User-provided reference diagram | F12: Utility Transformer Loss (MV->480V) | G12: 'Electricity Flow'!B36
A13: LV Switchgear Loss | B13: LVSW_Loss_MW = LVSW_Input_MW − ATS_Input_MW, where LVSW_Input = ATS_Input ÷ (1 − 0.2%) | C13: 0.2% = loss labeled on the reference diagram for the LV switchgear stage | D13: MW | E13: User-provided reference diagram | F13: LV Switchgear Loss | G13: 'Electricity Flow'!B34
A14: rPDU Loss | B14: rPDU_Loss_MW = rPDU_Input_MW − IT_Load_MW, where rPDU_Input = IT_Load ÷ (1 − 1%) | C14: 1% = the more conservative of the two loss values ('1%' and '2% Heat') labeled near the rPDU stage on the reference diagram | D14: MW | E14: User-provided reference diagram | F14: Rack PDU (rPDU) Loss | G14: 'Electricity Flow'!B24
A15: Renewable Contribution | B15: Renewable% = PowerMix_Solar% + PowerMix_Battery% | C15: Battery attributed as renewable-adjacent under the modeling assumption it is predominantly solar-charged | D15: % | E15: DOE 24/7 Carbon-Free Energy framework | F15: Solar/Battery Carbon Intensity assumption | G15: 'Electricity Flow'!B51
A16: Carbon Intensity | B16: CI = PowerMix_Grid% × CI_grid + PowerMix_Generator% × CI_diesel | C16: CI_grid = CAISO average grid carbon intensity; CI_diesel = standby generator emission factor | D16: kg CO2/kWh | E16: CAISO Fuel Mix; EPA eGRID; EPA GHG Emission Factors | F16: CAISO Grid Carbon Intensity; Diesel Generator Carbon Intensity | G16: 'Electricity Flow'!B52
... A23: Generator Reserve Capacity | B23: Gen_Reserve_MW = IT_Load_MW × GenCapacityMult | C23: GenCapacityMult = reliability-tier generator sizing multiplier; reserve capacity, not part of active dispatched load | D23: MW | E23: Uptime Institute Tier Standard: Topology | F23: Reliability Tier table (Generator Capacity Multiplier) | G23: 'Electricity Flow'!B45

Sheet References
A1: REFERENCES
A3: Prioritized peer-reviewed and industry sources used to build the Assumptions and Equations sheets.
A5: Organization | B5: Title / Publication | C5: Year | D5: URL / Citation
A6: ASHRAE TC9.9 | B6: Thermal Guidelines for Data Processing Environments (5th Ed.) / Liquid Cooling Guidelines | C6: 2021 | D6: www.ashrae.org (TC 9.9)
A7: Lawrence Berkeley National Laboratory (LBNL) | B7: United States Data Center Energy Usage Report | C7: 2016 | D7: eta.lbl.gov
A8: Uptime Institute | B8: Tier Standard: Topology; Annual Global Data Center Survey | C8: 2023 | D8: uptimeinstitute.com
A9: The Green Grid | B9: PUE: A Comprehensive Examination of the Metric; Water Usage Effectiveness (WUE) white paper | C9: 2011 | D9: www.thegreengrid.org
A10: U.S. Department of Energy (DOE) | B10: Better Buildings — Data Center Efficiency / Center of Expertise for Data Centers | C10: ongoing | D10: betterbuildingssolutioncenter.energy.gov
A11: National Renewable Energy Laboratory (NREL) | B11: PVWatts Calculator; Data Center Energy-Water Nexus reports | C11: various | D11: www.nrel.gov
A12: ENERGY STAR | B12: Data Center Energy Efficiency / PUE benchmarking | C12: ongoing | D12: www.energystar.gov
A13: California Independent System Operator (CAISO) | B13: Fuel Mix / Emissions data, real-time and historical | C13: ongoing | D13: www.caiso.com
A14: U.S. Environmental Protection Agency (EPA) | B14: eGRID (Emissions & Generation Resource Integrated Database); GHG Emission Factors Hub | C14: 2023 | D14: www.epa.gov/egrid
A15: RenewIT Project | B15: Green Data Centres — Renewable Energy in Data Centres | C15: 2016 | D15: cordis.europa.eu (RenewIT Project)
A16: California Energy Commission (CEC) | B16: California Building Climate Zones 1-16 | C16: ongoing | D16: www.energy.ca.gov
A17: Sankey Diagrams (community reference) | B17: Data centre-tagged Sankey diagram gallery | C17: ongoing | D17: www.sankey-diagrams.com/tag/data-centre/
A18: MEP Academy | B18: Data Center Power Flow: Utility to Server Rack Explained | C18: ongoing | D18: mepacademy.com/data-center-power-flow-utility-to-server-rack-explained/

Sheet Sankey Data Tables
A1: SANKEY DATA TABLES — Full Granular Node/Link Set, Matching the Reference Power-Flow Diagram
A3: Every Value cell is a live formula. Electrical: 30 links, full chain from Utility Grid/Solar/ESS/Generator through to CPU/GPU/TPU/ASIC/MPU/Fans. Cooling & Water: 21 links across three unit tracks sharing the HVAC and Facility Water Loop nodes — gal/yr for the open evaporative mass-balance, MW-th for the closed CDU/Direct-Liquid-Cooling secondary loop, and MW for the CRAH air-cooling branch. A renderer must NOT sum child-link values against a mismatched-unit parent inflow at those two nodes — treat each unit track as its own visual scale. Heat: 13 links, server heat + the four granular infrastructure losses converging on Heat Loss, through to Recoverable Heat's 5 end uses. Re-export (CSV/JSON) after changing any Inputs-sheet scenario selector. Color hexes match PROJECT_SCOPE.md Section 8 (v2.4 white-background, three-hue-family palette).
A5: Sankey | B5: Source Node | C5: Target Node | D5: Value | E5: Unit | F5: Color (hex)
A6: Electrical | B6: Utility Grid | C6: HV Transmission | D6: ='Electricity Flow'!B41 | E6: MW | F6: DB634C
A7: Electrical | B7: HV Transmission | C7: Main Medium Voltage BUS | D7: ='Electricity Flow'!B41 | E7: MW | F7: DB634C
A8: Electrical | B8: On-site Solar | C8: PV Inverter | D8: ='Electricity Flow'!B42 | E8: MW | F8: DB634C
A9: Electrical | B9: PV Inverter | C9: Main Medium Voltage BUS | D9: ='Electricity Flow'!B42 | E9: MW | F9: DB634C
A10: Electrical | B10: ESS | C10: PCS (Power Conversion System) | D10: ='Electricity Flow'!B43 | E10: MW | F10: DB634C
A11: Electrical | B11: PCS (Power Conversion System) | C11: Main Medium Voltage BUS | D11: ='Electricity Flow'!B43 | E11: MW | F11: DB634C
A12: Electrical | B12: Generator | C12: Generator Breaker | D12: ='Electricity Flow'!B44 | E12: MW | F12: DB634C
A13: Electrical | B13: Generator Breaker | C13: Main Medium Voltage BUS | D13: ='Electricity Flow'!B44 | E13: MW | F13: DB634C
A14: Electrical | B14: Main Medium Voltage BUS | C14: MV Switchgear | D14: ='Electricity Flow'!B37 | E14: MW | F14: DB634C
A15: Electrical | B15: MV Switchgear | C15: Utility Transformer (MV->480V) | D15: ='Electricity Flow'!B35 | E15: MW | F15: DB634C
A16: Electrical | B16: Utility Transformer (MV->480V) | C16: LV Switchgear | D16: ='Electricity Flow'!B33 | E16: MW | F16: DB634C
A17: Electrical | B17: Utility Transformer (MV->480V) | C17: Transformer Loss (0.5%) | D17: ='Electricity Flow'!B36 | E17: MW | F17: E3A467
A18: Electrical | B18: LV Switchgear | C18: Automatic Transfer Switch (ATS) | D18: ='Electricity Flow'!B32 | E18: MW | F18: DB634C
A19: Electrical | B19: LV Switchgear | C19: LV Switchgear Loss (0.2%) | D19: ='Electricity Flow'!B34 | E19: MW | F19: E3A467
A20: Electrical | B20: Automatic Transfer Switch (ATS) | C20: IT Infrastructure/Servers | D20: ='Electricity Flow'!B28 | E20: MW | F20: DB634C
A21: Electrical | B21: Automatic Transfer Switch (ATS) | C21: Lighting & Building Auxiliary Loads | D21: ='Electricity Flow'!B12 | E21: MW | F21: D98C2B
A22: Electrical | B22: IT Infrastructure/Servers | C22: Uninterruptible Power Supply (UPS, N+1) | D22: ='Electricity Flow'!B28 | E22: MW | F22: DB634C
A23: Electrical | B23: Uninterruptible Power Supply (UPS, N+1) | C23: UPS Heat Loss (2%) | D23: ='Electricity Flow'!B29 | E23: MW | F23: E3A467
A24: Electrical | B24: Uninterruptible Power Supply (UPS, N+1) | C24: Distribution Panels & Switchboards | D24: ='Electricity Flow'!B26 | E24: MW | F24: DB634C
A25: Electrical | B25: Distribution Panels & Switchboards | C25: Power Distribution Units (PDUs) | D25: ='Electricity Flow'!B25 | E25: MW | F25: DB634C
A26: Electrical | B26: Power Distribution Units (PDUs) | C26: Rack Power Distribution Units (rPDUs) | D26: ='Electricity Flow'!B23 | E26: MW | F26: DB634C
A27: Electrical | B27: Rack Power Distribution Units (rPDUs) | C27: rPDU Loss (1%) | D27: ='Electricity Flow'!B24 | E27: MW | F27: E3A467
A28: Electrical | B28: Rack Power Distribution Units (rPDUs) | C28: Server PSU | D28: ='Electricity Flow'!B10 | E28: MW | F28: DB634C
A29: Electrical | B29: Server PSU | C29: Motherboard | D29: ='Electricity Flow'!B10 | E29: MW | F29: DB634C
A30: Electrical | B30: Motherboard | C30: GPU (Graphics Processing Unit) | D30: ='Electricity Flow'!B15 | E30: MW | F30: DB634C
A31: Electrical | B31: Motherboard | C31: TPU (Tensor Processing Unit) | D31: ='Electricity Flow'!B16 | E31: MW | F31: DB634C
A32: Electrical | B32: Motherboard | C32: CPU | D32: ='Electricity Flow'!B17 | E32: MW | F32: DB634C
A33: Electrical | B33: Motherboard | C33: ASIC (Application-Specific Integrated Circuit) | D33: ='Electricity Flow'!B18 | E33: MW | F33: DB634C
A34: Electrical | B34: Motherboard | C34: Multi-Processor Servers (MPU) | D34: ='Electricity Flow'!B19 | E34: MW | F34: DB634C
A35: Electrical | B35: Motherboard | C35: Server Fans | D35: ='Electricity Flow'!B20 | E35: MW | F35: DB634C
A36: Cooling & Water | B36: Water Source | C36: Onsite Pump | D36: ='Water Flow'!B11 | E36: gal/yr | F36: 2E86C1
A37: Cooling & Water | B37: Onsite Pump | C37: HVAC | D37: ='Water Flow'!B11 | E37: gal/yr | F37: 2E86C1
A38: Cooling & Water | B38: HVAC | C38: Closed Loop Evaporative | D38: ='Water Flow'!B11 | E38: gal/yr | F38: 2E86C1
A39: Cooling & Water | B39: Closed Loop Evaporative | C39: Chiller | D39: ='Water Flow'!B11 | E39: gal/yr | F39: 2E86C1
A40: Cooling & Water | B40: Chiller | C40: Facility Water Loop | D40: ='Water Flow'!B11 | E40: gal/yr | F40: 2E86C1
A41: Cooling & Water | B41: Facility Water Loop | C41: Evaporated (Consumed) | D41: ='Water Flow'!B15 | E41: gal/yr | F41: 7FB8E0
A42: Cooling & Water | B42: Facility Water Loop | C42: Blowdown / Discharge | D42: ='Water Flow'!B16 | E42: gal/yr | F42: 2E86C1
...
